Workbook
Name Slicer_Category: #N/A
Name Slicer_Monthname: #N/A
Name Slicer_Region: #N/A
Name Slicer_Year: #N/A

Sheet Raw_Sales_Data
A2: Order ID | B2: Order Date | C2: Customer ID | D2: Product_ID | E2: Segment | G2: Region | H2: Category | I2: Quantity | J2: Product_Cost | K2: Sales
A3: ORD-1000 | B3: 45619 | C3: CUST-106 | D3: PROD-003 | E3: Consumer | F3: =TRIM(PROPER(G3)) -> North | G3: North | H3: Electronics | I3: 4
A4: ORD-1001 | B4: 45638 | C4: CUST-113 | D4: PROD-005 | E4: Corporate | F4: =TRIM(PROPER(G4)) -> Central | G4: Central | H4: Electronics | I4: 1
A5: ORD-1002 | B5: 45411 | C5: CUST-144 | D5: PROD-021 | E5: Home Office | F5: =TRIM(PROPER(G5)) -> Central | G5: Central | H5: Toys | I5: 4
A6: ORD-1003 | B6: 45571 | C6: CUST-100 | D6: PROD-009 | E6: Home Office | F6: =TRIM(PROPER(G6)) -> West | G6: West | H6: Clothing | I6: 5
A7: ORD-1004 | B7: 45373 | C7: CUST-121 | D7: PROD-013 | E7: Consumer | F7: =TRIM(PROPER(G7)) -> West | G7: West | H7: Home & Kitchen | I7: 4
A8: ORD-1005 | B8: 45344 | C8: CUST-116 | D8: PROD-016 | E8: Corporate | F8: =TRIM(PROPER(G8)) -> North | G8: North | H8: Office Supplies | I8: 14
A9: ORD-1006 | B9: 45314 | C9: CUST-140 | D9: PROD-021 | E9: Corporate | F9: =TRIM(PROPER(G9)) -> West | G9: West | H9: Toys | I9: 2
A10: ORD-1007 | B10: 45608 | C10: CUST-114 | D10: PROD-022 | E10: Home Office | F10: =TRIM(PROPER(G10)) -> East | G10: East | H10: Toys | I10: 2
A11: ORD-1008 | B11: 45440 | C11: CUST-123 | D11: PROD-006 | E11: Corporate | F11: =TRIM(PROPER(G11)) -> North | G11: North | H11: Clothing | I11: 5
A12: ORD-1009 | B12: 45375 | C12: CUST-143 | D12: PROD-012 | E12: Home Office | F12: =TRIM(PROPER(G12)) -> East | G12: East | H12: home & kitchen | I12: 5
A13: ORD-1010 | B13: 45623 | C13: CUST-129 | D13: PROD-022 | E13: Home Office | F13: =TRIM(PROPER(G13)) -> North | G13: North | H13: Toys | I13: 12
A14: ORD-1011 | B14: 45486 | C14: CUST-149 | D14: PROD-022 | E14: Home Office | F14: =TRIM(PROPER(G14)) -> East | G14: East | H14: Toys | I14: 6
... A57: ORD-1054 | B57: 45375 | C57: CUST-150 | D57: PROD-016 | E57: Consumer | F57: =TRIM(PROPER(G57)) -> South | G57: South | H57: Office Supplies | I57: 12
A58: ORD-1055 | B58: 45502 | C58: CUST-102 | D58: PROD-012 | F58: =TRIM(PROPER(G58)) -> South | G58: South | H58: Home & Kitchen | I58: 2
A59: ORD-1056 | B59: 45532 | C59: CUST-114 | D59: PROD-009 | F59: =TRIM(PROPER(G59)) -> South | G59: South | H59: Clothing | I59: 5
A60: ORD-1057 | B60: 45406 | C60: CUST-149 | D60: PROD-009 | E60: Corporate | F60: =TRIM(PROPER(G60)) -> North | G60: North | H60: Clothing | I60: 5
A61: ORD-1058 | B61: 45434 | C61: CUST-101 | D61: PROD-024 | E61: Home Office | F61: =TRIM(PROPER(G61)) -> East | G61: East | H61: Toys | I61: 14
A62: ORD-1059 | B62: 45351 | C62: CUST-127 | D62: PROD-010 | E62: Corporate | F62: =TRIM(PROPER(G62)) -> East | G62: East | H62: Clothing | I62: 1
A63: ORD-1060 | B63: 45468 | C63: CUST-136 | D63: PROD-020 | E63: Home Office | F63: =TRIM(PROPER(G63)) -> East | G63: East | H63: Office Supplies | I63: 2
A64: ORD-1061 | B64: 45389 | C64: CUST-134 | D64: PROD-004 | F64: =TRIM(PROPER(G64)) -> East | G64: East | H64: Electronics | I64: 9
A65: ORD-1062 | B65: 45643 | C65: CUST-139 | D65: PROD-014 | E65: Consumer | F65: =TRIM(PROPER(G65)) -> South | G65: South | H65: Home & Kitchen | I65: 11
A66: ORD-1063 | B66: 45452 | C66: CUST-125 | D66: PROD-015 | E66: Corporate | F66: =TRIM(PROPER(G66)) -> North | G66: North | H66: Home & Kitchen | I66: 11
A67: ORD-1064 | B67: 45648 | C67: CUST-124 | D67: PROD-022 | E67: Consumer | F67: =TRIM(PROPER(G67)) -> East | G67: East | H67: Toys | I67: 7
A68: ORD-1065 | B68: 45638 | C68: CUST-100 | D68: PROD-025 | E68: Corporate | F68: =TRIM(PROPER(G68)) -> South | G68: South | H68: toys | I68: 7
A69: ORD-1066 | B69: 45447 | C69: CUST-129 | D69: PROD-009 | E69: Home Office | F69: =TRIM(PROPER(G69)) -> East | G69: East | H69: Clothing | I69: 10
A70: ORD-1067 | B70: 45518 | C70: CUST-150 | D70: PROD-010 | E70: Corporate | F70: =TRIM(PROPER(G70)) -> West | G70: West | H70: Clothing | I70: 13
A71: ORD-1068 | B71: 45378 | C71: CUST-105 | D71: PROD-015 | E71: Home Office | F71: =TRIM(PROPER(G71)) -> North | G71: North | H71: home & kitchen | I71: 11
A72: ORD-1069 | B72: 45412 | C72: CUST-130 | D72: PROD-007 | E72: Consumer | F72: =TRIM(PROPER(G72)) -> East | G72: East | H72: Clothing | I72: 1
A73: ORD-1070 | B73: 45604 | C73: CUST-144 | D73: PROD-019 | E73: Home Office | F73: =TRIM(PROPER(G73)) -> North | G73: North | H73: Office Supplies | I73: 10
A74: ORD-1071 | B74: 45488 | C74: CUST-148 | D74: PROD-017 | E74: Consumer | F74: =TRIM(PROPER(G74)) -> West | G74: West | H74: Office Supplies | I74: 11
A75: ORD-1072 | B75: 45346 | C75: CUST-135 | D75: PROD-007 | E75: Home Office | F75: =TRIM(PROPER(G75)) -> West | G75: West | H75: Clothing | I75: 9
A76: ORD-1073 | B76: 45419 | C76: CUST-135 | D76: PROD-017 | E76: Corporate | F76: =TRIM(PROPER(G76)) -> North | G76: North | H76: office supplies | I76: 11
... A107: ORD-1104 | B107: 45448 | C107: CUST-147 | D107: PROD-006 | E107: Home Office | F107: =TRIM(PROPER(G107)) -> East | G107: East | H107: Clothing | I107: 4
A108: ORD-1105 | B108: 45566 | C108: CUST-137 | D108: PROD-007 | F108: =TRIM(PROPER(G108)) -> South | G108: South | H108: Clothing | I108: 8
A109: ORD-1106 | B109: 45560 | C109: CUST-111 | D109: PROD-011 | E109: Consumer | F109: =TRIM(PROPER(G109)) -> Central | G109: Central | H109: Home & Kitchen | I109: 5
A110: ORD-1107 | B110: 45446 | C110: CUST-135 | D110: PROD-022 | E110: Corporate | F110: =TRIM(PROPER(G110)) -> North | G110: North | H110: Toys | I110: 1
A111: ORD-1108 | B111: 45441 | C111: CUST-130 | D111: PROD-016 | E111: Consumer | F111: =TRIM(PROPER(G111)) -> South | G111: South | H111: Office Supplies | I111: 10
A112: ORD-1109 | B112: 45517 | C112: CUST-104 | D112: PROD-006 | E112: Corporate | F112: =TRIM(PROPER(G112)) -> East | G112: East | H112: Clothing | I112: 14
A113: ORD-1110 | B113: 45497 | C113: CUST-109 | D113: PROD-005 | E113: Home Office | F113: =TRIM(PROPER(G113)) -> West | G113: West | H113: Electronics | I113: 11
...

Sheet Product_Lookup
A2: Product_ID | B2: Product | C2: Product Cost
A3: PROD-001 | B3: Laptop | C3: $230.68
A4: PROD-002 | B4: Smartphone | C4: $216.22
A5: PROD-003 | B5: Tablet | C5: $146.06
A6: PROD-004 | B6: Monitor | C6: $145.48
A7: PROD-005 | B7: Headphones | C7: $178.83
A8: PROD-006 | B8: T-Shirt | C8: $107.34
A9: PROD-007 | B9: Jeans | C9: $33.22
A10: PROD-008 | B10: Jacket | C10: $10.11
A11: PROD-009 | B11: Sweater | C11: $84.57
A12: PROD-010 | B12: Socks | C12: $201.32
A13: PROD-011 | B13: Blender | C13: $156.44
... A27: PROD-025 | B27: Doll | C27: $32.94

Sheet Customer_Lookup
A2: Customer_ID | B2: Fullname | C2: Email_Address | D2: Date_of_Birth | E2: Country_Location
A3: CUST-100 | B3: John Smith | C3: john.smith100@email.com | D3: 26153 | E3: USA
A4: CUST-101 | B4: Jane Brown | C4: jane.brown101@email.com | D4: 28842 | E4: Canada
A5: CUST-102 | B5: Michael Miller | C5: michael.miller102@email.com | D5: 23511 | E5: UK
A6: CUST-103 | B6: Sarah Martinez | C6: sarah.martinez103@email.com | D6: 31187 | E6: Australia
A7: CUST-104 | B7: David Gonzalez | C7: david.gonzalez104@email.com | D7: 32505 | E7: Germany
A8: CUST-105 | B8: Emily Thomas | C8: emily.thomas105@email.com | D8: 23735 | E8: France
A9: CUST-106 | B9: Robert Jackson | C9: robert.jackson106@email.com | D9: 24233 | E9: Spain
A10: CUST-107 | B10: Jessica Johnson | C10: jessica.johnson107@email.com | D10: 34413 | E10: Italy
A11: CUST-108 | B11: James Jones | C11: james.jones108@email.com | D11: 24948 | E11: Netherlands
A12: CUST-109 | B12: Mary Davis | C12: mary.davis109@email.com | D12: 34985 | E12: Belgium
A13: CUST-110 | B13: William Hernandez | C13: william.hernandez110@email.com | D13: 30277 | E13: Sweden
A14: CUST-111 | B14: Patricia Wilson | C14: patricia.wilson111@email.com | D14: 27749 | E14: Norway
... A103: CUST-200 | B103: John Smith | C103: john.smith200@email.com | D103: 22107 | E103: USA

Sheet Raw_Sales_Data _Cleaned
A1: Order ID | B1: Order Date | C1: Customer ID | D1: Product_ID | E1: Segment | F1: Region | G1: Category | H1: Quantity | I1: Product_Cost | J1: Day of week | K1: Monthname | L1: Year | M1: OR | N1: AND | O1: Order Status | P1: Discounted Amount | Q1: Products | R1: Sales | S1: Discounted Rates
A2: ORD-1000 | B2: 45619 | C2: CUST-106 | D2: PROD-003 | E2: Consumer | F2: North | G2: Electronics | H2: 4 | I2: =VLOOKUP(D2,Product_Lookup!$A$2:$C$27,3,FALSE) -> $146.06 | J2: =TEXT(B2, "dddd") -> Saturday | K2: =TEXT(B2, "mmmm") -> November | L2: =YEAR(B2) -> 2024 | M2: =OR(J2="Saturday", J2="Sunday") -> TRUE | N2: =AND(R2>750, H2>5) -> FALSE | O2: =IF(R2>500,"Large Order","Standard order") -> Large Order | P2: =I2*$S$2 -> 7.303 | Q2: =VLOOKUP(D3,Product_Lookup!$A$2:$C$27,2,FALSE) -> Headphones | R2: =H2*I2 -> 584.24 | S2: 0.05
A3: ORD-1001 | B3: 45638 | C3: CUST-113 | D3: PROD-005 | E3: Corporate | F3: Central | G3: Electronics | H3: 1 | I3: =VLOOKUP(D3,Product_Lookup!$A$2:$C$27,3,FALSE) -> $178.83 | J3: =TEXT(B3, "dddd") -> Thursday | K3: =TEXT(B3, "mmmm") -> December | L3: =YEAR(B3) -> 2024 | M3: =OR(J3="Saturday", J3="Sunday") -> FALSE | N3: =AND(R3>750, H3>5) -> FALSE | O3: =IF(R3>500,"Large Order","Standard order") -> Standard order | P3: =I3*$S$2 -> 8.9415 | Q3: =VLOOKUP(D4,Product_Lookup!$A$2:$C$27,2,FALSE) -> Action Figure | R3: =H3*I3 -> 178.83 | S3: 0.1
A4: ORD-1002 | B4: 45411 | C4: CUST-144 | D4: PROD-021 | E4: Home Office | F4: Central | G4: Toys | H4: 4 | I4: =VLOOKUP(D4,Product_Lookup!$A$2:$C$27,3,FALSE) -> $88.18 | J4: =TEXT(B4, "dddd") -> Monday | K4: =TEXT(B4, "mmmm") -> April | L4: =YEAR(B4) -> 2024 | M4: =OR(J4="Saturday", J4="Sunday") -> FALSE | N4: =AND(R4>750, H4>5) -> FALSE | O4: =IF(R4>500,"Large Order","Standard order") -> Standard order | P4: =I4*$S$2 -> 4.409 | Q4: =VLOOKUP(D5,Product_Lookup!$A$2:$C$27,2,FALSE) -> Sweater | R4: =H4*I4 -> 352.72 | S4: 0.15
A5: ORD-1003 | B5: 45571 | C5: CUST-100 | D5: PROD-009 | E5: Home Office | F5: West | G5: Clothing | H5: 5 | I5: =VLOOKUP(D5,Product_Lookup!$A$2:$C$27,3,FALSE) -> $84.57 | J5: =TEXT(B5, "dddd") -> Sunday | K5: =TEXT(B5, "mmmm") -> October | L5: =YEAR(B5) -> 2024 | M5: =OR(J5="Saturday", J5="Sunday") -> TRUE | N5: =AND(R5>750, H5>5) -> FALSE | O5: =IF(R5>500,"Large Order","Standard order") -> Standard order | P5: =I5*$S$2 -> 4.2285 | Q5: =VLOOKUP(D6,Product_Lookup!$A$2:$C$27,2,FALSE) -> Coffee Maker | R5: =H5*I5 -> 422.85
A6: ORD-1004 | B6: 45373 | C6: CUST-121 | D6: PROD-013 | E6: Consumer | F6: West | G6: Home & Kitchen | H6: 4 | I6: =VLOOKUP(D6,Product_Lookup!$A$2:$C$27,3,FALSE) -> $230.34 | J6: =TEXT(B6, "dddd") -> Friday | K6: =TEXT(B6, "mmmm") -> March | L6: =YEAR(B6) -> 2024 | M6: =OR(J6="Saturday", J6="Sunday") -> FALSE | N6: =AND(R6>750, H6>5) -> FALSE | O6: =IF(R6>500,"Large Order","Standard order") -> Large Order | P6: =I6*$S$2 -> 11.517 | Q6: =VLOOKUP(D7,Product_Lookup!$A$2:$C$27,2,FALSE) -> Stapler | R6: =H6*I6 -> 921.36
A7: ORD-1005 | B7: 45344 | C7: CUST-116 | D7: PROD-016 | E7: Corporate | F7: North | G7: Office Supplies | H7: 14 | I7: =VLOOKUP(D7,Product_Lookup!$A$2:$C$27,3,FALSE) -> $64.61 | J7: =TEXT(B7, "dddd") -> Thursday | K7: =TEXT(B7, "mmmm") -> February | L7: =YEAR(B7) -> 2024 | M7: =OR(J7="Saturday", J7="Sunday") -> FALSE | N7: =AND(R7>750, H7>5) -> TRUE | O7: =IF(R7>500,"Large Order","Standard order") -> Large Order | P7: =I7*$S$2 -> 3.2305 | Q7: =VLOOKUP(D8,Product_Lookup!$A$2:$C$27,2,FALSE) -> Action Figure | R7: =H7*I7 -> 904.54
A8: ORD-1006 | B8: 45314 | C8: CUST-140 | D8: PROD-021 | E8: Corporate | F8: West | G8: Toys | H8: 2 | I8: =VLOOKUP(D8,Product_Lookup!$A$2:$C$27,3,FALSE) -> $88.18 | J8: =TEXT(B8, "dddd") -> Tuesday | K8: =TEXT(B8, "mmmm") -> January | L8: =YEAR(B8) -> 2024 | M8: =OR(J8="Saturday", J8="Sunday") -> FALSE | N8: =AND(R8>750, H8>5) -> FALSE | O8: =IF(R8>500,"Large Order","Standard order") -> Standard order | P8: =I8*$S$2 -> 4.409 | Q8: =VLOOKUP(D9,Product_Lookup!$A$2:$C$27,2,FALSE) -> Board Game | R8: =H8*I8 -> 176.36
A9: ORD-1007 | B9: 45608 | C9: CUST-114 | D9: PROD-022 | E9: Home Office | F9: East | G9: Toys | H9: 2 | I9: =VLOOKUP(D9,Product_Lookup!$A$2:$C$27,3,FALSE) -> $86.6 | J9: =TEXT(B9, "dddd") -> Tuesday | K9: =TEXT(B9, "mmmm") -> November | L9: =YEAR(B9) -> 2024 | M9: =OR(J9="Saturday", J9="Sunday") -> FALSE | N9: =AND(R9>750, H9>5) -> FALSE | O9: =IF(R9>500,"Large Order","Standard order") -> Standard order | P9: =I9*$S$2 -> 4.33 | Q9: =VLOOKUP(D10,Product_Lookup!$A$2:$C$27,2,FALSE) -> T-Shirt | R9: =H9*I9 -> 173.2
A10: ORD-1008 | B10: 45440 | C10: CUST-123 | D10: PROD-006 | E10: Corporate | F10: North | G10: Clothing | H10: 5 | I10: =VLOOKUP(D10,Product_Lookup!$A$2:$C$27,3,FALSE) -> $107.34 | J10: =TEXT(B10, "dddd") -> Tuesday | K10: =TEXT(B10, "mmmm") -> May | L10: =YEAR(B10) -> 2024 | M10: =OR(J10="Saturday", J10="Sunday") -> FALSE | N10: =AND(R10>750, H10>5) -> FALSE | O10: =IF(R10>500,"Large Order","Standard order") -> Large Order | P10: =I10*$S$2 -> 5.367 | Q10: =VLOOKUP(D11,Product_Lookup!$A$2:$C$27,2,FALSE) -> Toaster | R10: =H10*I10 -> 536.7
A11: ORD-1009 | B11: 45375 | C11: CUST-143 | D11: PROD-012 | E11: Home Office | F11: East | G11: Home & Kitchen | H11: 5 | I11: =VLOOKUP(D11,Product_Lookup!$A$2:$C$27,3,FALSE) -> $208.85 | J11: =TEXT(B11, "dddd") -> Sunday | K11: =TEXT(B11, "mmmm") -> March | L11: =YEAR(B11) -> 2024 | M11: =OR(J11="Saturday", J11="Sunday") -> TRUE | N11: =AND(R11>750, H11>5) -> FALSE | O11: =IF(R11>500,"Large Order","Standard order") -> Large Order | P11: =I11*$S$2 -> 10.4425 | Q11: =VLOOKUP(D12,Product_Lookup!$A$2:$C$27,2,FALSE) -> Board Game | R11: =H11*I11 -> 1044.25
A12: ORD-1010 | B12: 45623 | C12: CUST-129 | D12: PROD-022 | E12: Home Office | F12: North | G12: Toys | H12: 12 | I12: =VLOOKUP(D12,Product_Lookup!$A$2:$C$27,3,FALSE) -> $86.6 | J12: =TEXT(B12, "dddd") -> Wednesday | K12: =TEXT(B12, "mmmm") -> November | L12: =YEAR(B12) -> 2024 | M12: =OR(J12="Saturday", J12="Sunday") -> FALSE | N12: =AND(R12>750, H12>5) -> TRUE | O12: =IF(R12>500,"Large Order","Standard order") -> Large Order | P12: =I12*$S$2 -> 4.33 | Q12: =VLOOKUP(D13,Product_Lookup!$A$2:$C$27,2,FALSE) -> Board Game | R12: =H12*I12 -> 1039.2
A13: ORD-1011 | B13: 45486 | C13: CUST-149 | D13: PROD-022 | E13: Home Office | F13: East | G13: Toys | H13: 6 | I13: =VLOOKUP(D13,Product_Lookup!$A$2:$C$27,3,FALSE) -> $86.6 | J13: =TEXT(B13, "dddd") -> Saturday | K13: =TEXT(B13, "mmmm") -> July | L13: =YEAR(B13) -> 2024 | M13: =OR(J13="Saturday", J13="Sunday") -> TRUE | N13: =AND(R13>750, H13>5) -> FALSE | O13: =IF(R13>500,"Large Order","Standard order") -> Large Order | P13: =I13*$S$2 -> 4.33 | Q13: =VLOOKUP(D14,Product_Lookup!$A$2:$C$27,2,FALSE) -> Tablet | R13: =H13*I13 -> 519.6
A14: ORD-1012 | B14: 45320 | C14: CUST-136 | D14: PROD-003 | E14: Corporate | F14: South | G14: Electronics | H14: 5 | I14: =VLOOKUP(D14,Product_Lookup!$A$2:$C$27,3,FALSE) -> $146.06 | J14: =TEXT(B14, "dddd") -> Monday | K14: =TEXT(B14, "mmmm") -> January | L14: =YEAR(B14) -> 2024 | M14: =OR(J14="Saturday", J14="Sunday") -> FALSE | N14: =AND(R14>750, H14>5) -> FALSE | O14: =IF(R14>500,"Large Order","Standard order") -> Large Order | P14: =I14*$S$2 -> 7.303 | Q14: =VLOOKUP(D15,Product_Lookup!$A$2:$C$27,2,FALSE) -> Desk Lamp | R14: =H14*I14 -> 730.3
A15: ORD-1013 | B15: 45453 | C15: CUST-108 | D15: PROD-019 | E15: Home Office | F15: South | G15: Office Supplies | H15: 8 | I15: =VLOOKUP(D15,Product_Lookup!$A$2:$C$27,3,FALSE) -> $101.96 | J15: =TEXT(B15, "dddd") -> Monday | K15: =TEXT(B15, "mmmm") -> June | L15: =YEAR(B15) -> 2024 | M15: =OR(J15="Saturday", J15="Sunday") -> FALSE | N15: =AND(R15>750, H15>5) -> TRUE | O15: =IF(R15>500,"Large Order","Standard order") -> Large Order | P15: =I15*$S$2 -> 5.098 | Q15: =VLOOKUP(D16,Product_Lookup!$A$2:$C$27,2,FALSE) -> Puzzle | R15: =H15*I15 -> 815.68
A16: ORD-1014 | B16: 45418 | C16: CUST-137 | D16: PROD-023 | E16: Home Office | F16: Central | G16: Toys | H16: 10 | I16: =VLOOKUP(D16,Product_Lookup!$A$2:$C$27,3,FALSE) -> $46.19 | J16: =TEXT(B16, "dddd") -> Monday | K16: =TEXT(B16, "mmmm") -> May | L16: =YEAR(B16) -> 2024 | M16: =OR(J16="Saturday", J16="Sunday") -> FALSE | N16: =AND(R16>750, H16>5) -> FALSE | O16: =IF(R16>500,"Large Order","Standard order") -> Standard order | P16: =I16*$S$2 -> 2.3095 | Q16: =VLOOKUP(D17,Product_Lookup!$A$2:$C$27,2,FALSE) -> Jeans | R16: =H16*I16 -> 461.9
... A3300: ORD-4298 | B3300: 45316 | C3300: CUST-141 | D3300: PROD-015 | E3300: Home Office | F3300: East | G3300: Clothing | H3300: 7 | I3300: =VLOOKUP(D3300,Product_Lookup!$A$2:$C$27,3,FALSE) -> $211.9 | J3300: =TEXT(B3300, "dddd") -> Thursday | K3300: =TEXT(B3300, "mmmm") -> January | L3300: =YEAR(B3300) -> 2024 | M3300: =OR(J3300="Saturday", J3300="Sunday") -> FALSE | N3300: =AND(R3300>750, H3300>5) -> TRUE | O3300: =IF(R3300>500,"Large Order","Standard order") -> Large Order | P3300: =I3300*$S$2 -> 10.595 | Q3300: =VLOOKUP(D3301,Product_Lookup!$A$2:$C$27,2,FALSE) -> Blender | R3300: =H3300*I3300 -> 1483.3
A3301: ORD-4299 | B3301: 45572 | C3301: CUST-182 | D3301: PROD-011 | E3301: Home Office | F3301: West | G3301: Home & Kitchen | H3301: 6 | I3301: =VLOOKUP(D3301,Product_Lookup!$A$2:$C$27,3,FALSE) -> $156.44 | J3301: =TEXT(B3301, "dddd") -> Monday | K3301: =TEXT(B3301, "mmmm") -> October | L3301: =YEAR(B3301) -> 2024 | M3301: =OR(J3301="Saturday", J3301="Sunday") -> FALSE | N3301: =AND(R3301>750, H3301>5) -> TRUE | O3301: =IF(R3301>500,"Large Order","Standard order") -> Large Order | P3301: =I3301*$S$2 -> 7.822 | Q3301: Unknown | R3301: =H3301*I3301 -> 938.64

Sheet Input
A1: Total Sales Amount | F1: Region | G1: Target Sales
A2: =SUM('Raw_Sales_Data _Cleaned'!R2:R3301) -> 4191450.4 | J2: Key Metrics
J3: Revenue by Top 5 Products
A4: Average Order Value | J4: Revenue by Product Categories
A5: =AVERAGE('Raw_Sales_Data _Cleaned'!R2:R3301) -> 1270.1365 | J5: Total Quantity by Category
J6: Revenue by Region
A7: Number of orders | J7: Monthly Sales Trend
A8: =COUNTA('Raw_Sales_Data _Cleaned'!$A$2:$A$3301) -> 3300
A10: Median Quantity Sold per Order | J10: Insights
A11: =MEDIAN('Raw_Sales_Data _Cleaned'!H3283:H3301) -> 9 | I11: 1 | J11: Revenue by Top 5 Products
J12: Stapler generated the highest revenue with a total amount of $203,693.31 among the 5 products while smartphone was the least of the 5 products
A13: Total Sales for "Electronics" | I13: 2 | J13: Revenue by Product categories
A14: =SUMIF('Raw_Sales_Data _Cleaned'!$G$2:$G$6583, "Electronics", 'Raw_Sales_Data _Cleaned'!R2:R3301) -> 816382.14 | J14: Office supplier product category produced the highest revenue sales with $860,86.24 leaving electronics as the least category
I15: 3 | J15: Total Quantity by Category
A16: Average sales for North region | J16: The toys, clothing and Home Kitchen equipment has the same proportion o quantity sold by 20% while office suplier had the largest proportion o quantity sold by 21%
A17: =AVERAGEIF('Raw_Sales_Data _Cleaned'!$F$2:$F$3300,"North",'Raw_Sales_Data _Cleaned'!R2:R3301) -> 1251.3454 | I17: 4 | J17: Revenue by Region
J18: The East region was seen to dominate the sales revenue with a total sum of $888,726.30 while south had the least contribution
A19: Orders Count with Quantity | I19: 5 | J19: Monthly Sales Trend
A20: =COUNTIF('Raw_Sales_Data _Cleaned'!H2:H3301, ">5") -> 2434 | J20: In monthly sales across the year 2024, the higest sales revenue was recorded in October with a total sum of $406,552.40 while the lowest revenue was
J21: 300805.61
A22: Total Profits for clothing category in west Region
A23: =SUMIFS('Raw_Sales_Data _Cleaned'!$R$2:$R$3301, 'Raw_Sales_Data _Cleaned'!$G$2:$G$3301, "Clothing", 'Raw_Sales_Data _Cleaned'!$F$2:$F$3301, "West") -> 162195.95 | J23: Recommendations
I24: 1 | J24: The least product "Smartphone" should be moved to the high performing growth region "East" to improve the sales revenue
I25: 2 | J25: During the Monthly sales trend, October has the highest sales revenue and the company should supply more products during this period of sales to ensure income revenue
I26: 3 | J26: The company should prioritize the office supplier product caetegory across regions to ensure and maintain the sales perormance in generaing profits

Sheet Pivot Tables
A1: Sales By Top 5 categories | E1: Sales by Regions | H1: Average Quantity sold by segment
A3: Row Labels | B3: Sum of Sales | E3: Row Labels | F3: Sum of Sales | H3: Row Labels | I3: Average of Quantity
A4: Electronics | B4: 816382.14 | E4: South | F4: 809831.39 | H4: Consumer | I4: 10.397424
A5: Clothing | B5: 821087.41 | E5: West | F5: 823085.74 | H5: Corporate | I5: 10.12213
A6: Toys | B6: 837011.35 | E6: Central | F6: 830154.32 | H6: Home Office | I6: 10.32675
A7: Home & Kitchen | B7: 856183.27 | E7: North | F7: 839652.76 | H7: Unknown | I7: 6.6
A8: Office Supplies | B8: 860786.24 | E8: East | F8: 888726.2 | H8: Grand Total | I8: 10.271212
A9: Grand Total | B9: 4191450.4 | E9: Grand Total | F9: 4191450.4
A12: Monthly Sales Trend | E12: Sales by Product | H12: Total Quantity Sold by Category
A14: Row Labels | B14: Sum of Sales | E14: Row Labels | F14: Sum of Sales | H14: Row Labels | I14: Sum of Quantity
A15: January | B15: 329754.35 | E15: Smartphone | F15: 185519.41 | H15: Clothing | I15: 0.1958696
A16: February | B16: 300805.61 | E16: Lego Set | F16: 188083.87 | H16: Electronics | I16: 0.19035256
A17: March | B17: 349502.47 | E17: T-Shirt | F17: 188715.31 | H17: Home & Kitchen | I17: 0.19970497
A18: April | B18: 311993.55 | E18: Air Fryer | F18: 203127.31 | H18: Office Supplies | I18: 0.20876235
A19: May | B19: 362602.4 | E19: Stapler | F19: 203693.31 | H19: Toys | I19: 0.20531052
A20: June | B20: 321455.08 | E20: Grand Total | F20: 969139.21 | H20: Grand Total | I20: 1
A21: July | B21: 406002.67
A22: August | B22: 364609.85
A23: September | B23: 300978.77
A24: October | B24: 406552.4
A25: November | B25: 361404.55
A26: December | B26: 375788.71
A27: Grand Total | B27: 4191450.4

Sheet Dashboard
